<?xml version="1.0"?>
<robot name="trilobyte" xmlns:xacro="http://ros.org/wiki/xacro">

  <link name="base_footprint" />

  <joint name="base_joint" type="fixed">
    <parent link="base_link" />
    <child link="base_footprint" />
    <origin xyz="0 0 0.05" rpy="0 0 0" />
  </joint>

  <link name="base_link">
    <visual>
        <origin xyz="0.0 0.0 0.02" rpy="0 0 1.57" />
            <geometry>
                <mesh filename="package://trilobyte_description/meshes/trilobyte_base_link.obj"/>
            </geometry>
    </visual>
  </link>

  <joint name="joint_base_lifter" type="revolute">
    <parent link="base_link" />
    <child link="lifter" />
    <limit effort="10.0" velocity="5.0" />
  </joint>

  <joint name="joint_lifter_gripper_left" type="revolute">
    <parent link="lifter" />
    <child link="gripper_left" />
    <limit effort="10.0" velocity="5.0" />

  </joint>

  <joint name="joint_lifter_gripper_right" type="revolute">
    <parent link="lifter" />
    <child link="gripper_right" />
    <limit effort="10.0" velocity="5.0" />

  </joint>

  <link name="lifter">
    <visual>
      <origin xyz="0.0 0.0 0.02" rpy="0 0 1.57" />
      <geometry>
          <mesh filename="package://trilobyte_description/meshes/lifter.obj"/>
      </geometry>
    </visual>
  </link>

  <link name="gripper_left">
  </link>
  <link name = "gripper_right">
  </link>

  <!-- Left Wheel -->
  <link name="wheel_left">
    <visual>
      <origin xyz="0 0.06 -0.03" rpy="0 0 1.57" />
        <geometry>
          <mesh filename="package://trilobyte_description/meshes/wheel_left.obj"/>
        </geometry>
    </visual>
  </link>

  <joint name="joint_wheel_left" type="continuous">
    <parent link="base_link" />
    <child link="wheel_left" />
    <origin xyz="0 0.12 0" rpy="0 0 0" />
    <axis xyz= "0 1 0" />
  </joint>

  <!-- Right Wheel -->
  <link name="wheel_right">
    <visual>
      <origin xyz="0.0 -0.03 -0.03" rpy="0 0 -1.57" />
        <geometry>
          <mesh filename="package://trilobyte_description/meshes/wheel_right.obj"/>
        </geometry>
    </visual>
  </link>

  <joint name="joint_wheel_right" type="continuous">
    <parent link="base_link" />
    <child link="wheel_right" />
    <origin xyz="0 -0.12 0" rpy="0 0 0" />
    <axis xyz= "0 1 0" />
  </joint>

  <!-- Caster Wheel -->

  <link name="wheel_caster">
    <visual>
      <origin xyz="0.0 0.0 0.0" rpy="0 0 0" />
        <geometry>
          <mesh filename="package://trilobyte_description/meshes/caster_ball.obj"/>
        </geometry>
    </visual>
  </link>

  <joint name="joint_wheel_caster" type="fixed">
    <parent link="base_link" />
    <child link="wheel_caster" />
    <origin xyz="-0.07 -0.005 -0.02" rpy="0 0 0" />
    <!-- <axis xyz= "0 0 0" /> -->
  </joint>

  <link name="base_laser">
  </link>

 <joint name="joint_base_laser" type="fixed">
  <parent link="base_link" />
  <child link="base_laser" />
  <origin xyz="0 0.06 0.12" rpy="0 0 0" />
 </joint>

</robot>
